
Currently Loaded Modules:
  1) tensorflow/2.6.0

 

2025-07-09 08:51:05.245029: W tensorflow/core/common_runtime/gpu/gpu_device.cc:1938] TensorFlow was not built with CUDA kernel binaries compatible with compute capability 10.0. CUDA kernels will be jit-compiled from PTX, which could take 30 minutes or longer.
2025-07-09 08:52:01.307455: W tensorflow/core/common_runtime/gpu/gpu_device.cc:1938] TensorFlow was not built with CUDA kernel binaries compatible with compute capability 10.0. CUDA kernels will be jit-compiled from PTX, which could take 30 minutes or longer.
2025-07-09 08:52:01.307786: I tensorflow/core/platform/cpu_feature_guard.cc:142] This TensorFlow binary is optimized with oneAPI Deep Neural Network Library (oneDNN) to use the following CPU instructions in performance-critical operations:  AVX2 AVX512F FMA
To enable them in other operations, rebuild TensorFlow with the appropriate compiler flags.
2025-07-09 08:52:01.313181: W tensorflow/core/common_runtime/gpu/gpu_device.cc:1938] TensorFlow was not built with CUDA kernel binaries compatible with compute capability 10.0. CUDA kernels will be jit-compiled from PTX, which could take 30 minutes or longer.
2025-07-09 08:52:22.048011: I tensorflow/core/common_runtime/gpu/gpu_device.cc:1510] Created device /job:localhost/replica:0/task:0/device:GPU:0 with 180450 MB memory:  -> device: 0, name: NVIDIA B200, pci bus id: 0000:9d:00.0, compute capability: 10.0
2025-07-09 08:52:24.545705: I tensorflow/compiler/mlir/mlir_graph_optimization_pass.cc:185] None of the MLIR Optimization Passes are enabled (registered 2)
2025-07-09 08:52:24.798558: W tensorflow/core/framework/op_kernel.cc:1680] Invalid argument: TypeError: `generator` yielded an element of ((TensorSpec(shape=(40, 420), dtype=tf.float64, name=None), SparseTensorSpec(TensorShape([40, 40]), tf.float32), TensorSpec(shape=(40,), dtype=tf.int64, name=None)), TensorSpec(shape=(8, 5, 12), dtype=tf.int64, name=None)) where an element of ((TensorSpec(shape=(None, 420), dtype=tf.float64, name=None), SparseTensorSpec(TensorShape([None, None]), tf.float32), TensorSpec(shape=(None,), dtype=tf.int64, name=None)), TensorSpec(shape=(None, 12), dtype=tf.int64, name=None)) was expected.
Traceback (most recent call last):

  File "/home/jruizmunoz/anaconda3/envs/ghifo_py38/lib/python3.8/site-packages/tensorflow/python/ops/script_ops.py", line 247, in __call__
    return func(device, token, args)

  File "/home/jruizmunoz/anaconda3/envs/ghifo_py38/lib/python3.8/site-packages/tensorflow/python/ops/script_ops.py", line 135, in __call__
    ret = self._func(*args)

  File "/home/jruizmunoz/anaconda3/envs/ghifo_py38/lib/python3.8/site-packages/tensorflow/python/autograph/impl/api.py", line 645, in wrapper
    return func(*args, **kwargs)

  File "/home/jruizmunoz/anaconda3/envs/ghifo_py38/lib/python3.8/site-packages/tensorflow/python/data/ops/dataset_ops.py", line 977, in generator_py_func
    raise TypeError(

TypeError: `generator` yielded an element of ((TensorSpec(shape=(40, 420), dtype=tf.float64, name=None), SparseTensorSpec(TensorShape([40, 40]), tf.float32), TensorSpec(shape=(40,), dtype=tf.int64, name=None)), TensorSpec(shape=(8, 5, 12), dtype=tf.int64, name=None)) where an element of ((TensorSpec(shape=(None, 420), dtype=tf.float64, name=None), SparseTensorSpec(TensorShape([None, None]), tf.float32), TensorSpec(shape=(None,), dtype=tf.int64, name=None)), TensorSpec(shape=(None, 12), dtype=tf.int64, name=None)) was expected.


<frozen importlib._bootstrap>:219: RuntimeWarning: scipy._lib.messagestream.MessageStream size changed, may indicate binary incompatibility. Expected 56 from C header, got 64 from PyObject
Traceback (most recent call last):
  File "train_gnn.py", line 298, in <module>
    main()
  File "train_gnn.py", line 290, in main
    model.fit(loader.load(), steps_per_epoch=loader.steps_per_epoch, epochs=20)
  File "/home/jruizmunoz/anaconda3/envs/ghifo_py38/lib/python3.8/site-packages/keras/engine/training.py", line 1184, in fit
    tmp_logs = self.train_function(iterator)
  File "/home/jruizmunoz/anaconda3/envs/ghifo_py38/lib/python3.8/site-packages/tensorflow/python/eager/def_function.py", line 885, in __call__
    result = self._call(*args, **kwds)
  File "/home/jruizmunoz/anaconda3/envs/ghifo_py38/lib/python3.8/site-packages/tensorflow/python/eager/def_function.py", line 950, in _call
    return self._stateless_fn(*args, **kwds)
  File "/home/jruizmunoz/anaconda3/envs/ghifo_py38/lib/python3.8/site-packages/tensorflow/python/eager/function.py", line 3039, in __call__
    return graph_function._call_flat(
  File "/home/jruizmunoz/anaconda3/envs/ghifo_py38/lib/python3.8/site-packages/tensorflow/python/eager/function.py", line 1963, in _call_flat
    return self._build_call_outputs(self._inference_function.call(
  File "/home/jruizmunoz/anaconda3/envs/ghifo_py38/lib/python3.8/site-packages/tensorflow/python/eager/function.py", line 591, in call
    outputs = execute.execute(
  File "/home/jruizmunoz/anaconda3/envs/ghifo_py38/lib/python3.8/site-packages/tensorflow/python/eager/execute.py", line 59, in quick_execute
    tensors = pywrap_tfe.TFE_Py_Execute(ctx._handle, device_name, op_name,
tensorflow.python.framework.errors_impl.InvalidArgumentError: 2 root error(s) found.
  (0) Invalid argument:  TypeError: `generator` yielded an element of ((TensorSpec(shape=(40, 420), dtype=tf.float64, name=None), SparseTensorSpec(TensorShape([40, 40]), tf.float32), TensorSpec(shape=(40,), dtype=tf.int64, name=None)), TensorSpec(shape=(8, 5, 12), dtype=tf.int64, name=None)) where an element of ((TensorSpec(shape=(None, 420), dtype=tf.float64, name=None), SparseTensorSpec(TensorShape([None, None]), tf.float32), TensorSpec(shape=(None,), dtype=tf.int64, name=None)), TensorSpec(shape=(None, 12), dtype=tf.int64, name=None)) was expected.
Traceback (most recent call last):

  File "/home/jruizmunoz/anaconda3/envs/ghifo_py38/lib/python3.8/site-packages/tensorflow/python/ops/script_ops.py", line 247, in __call__
    return func(device, token, args)

  File "/home/jruizmunoz/anaconda3/envs/ghifo_py38/lib/python3.8/site-packages/tensorflow/python/ops/script_ops.py", line 135, in __call__
    ret = self._func(*args)

  File "/home/jruizmunoz/anaconda3/envs/ghifo_py38/lib/python3.8/site-packages/tensorflow/python/autograph/impl/api.py", line 645, in wrapper
    return func(*args, **kwargs)

  File "/home/jruizmunoz/anaconda3/envs/ghifo_py38/lib/python3.8/site-packages/tensorflow/python/data/ops/dataset_ops.py", line 977, in generator_py_func
    raise TypeError(

TypeError: `generator` yielded an element of ((TensorSpec(shape=(40, 420), dtype=tf.float64, name=None), SparseTensorSpec(TensorShape([40, 40]), tf.float32), TensorSpec(shape=(40,), dtype=tf.int64, name=None)), TensorSpec(shape=(8, 5, 12), dtype=tf.int64, name=None)) where an element of ((TensorSpec(shape=(None, 420), dtype=tf.float64, name=None), SparseTensorSpec(TensorShape([None, None]), tf.float32), TensorSpec(shape=(None,), dtype=tf.int64, name=None)), TensorSpec(shape=(None, 12), dtype=tf.int64, name=None)) was expected.


	 [[{{node EagerPyFunc}}]]
	 [[IteratorGetNext]]
  (1) Invalid argument:  TypeError: `generator` yielded an element of ((TensorSpec(shape=(40, 420), dtype=tf.float64, name=None), SparseTensorSpec(TensorShape([40, 40]), tf.float32), TensorSpec(shape=(40,), dtype=tf.int64, name=None)), TensorSpec(shape=(8, 5, 12), dtype=tf.int64, name=None)) where an element of ((TensorSpec(shape=(None, 420), dtype=tf.float64, name=None), SparseTensorSpec(TensorShape([None, None]), tf.float32), TensorSpec(shape=(None,), dtype=tf.int64, name=None)), TensorSpec(shape=(None, 12), dtype=tf.int64, name=None)) was expected.
Traceback (most recent call last):

  File "/home/jruizmunoz/anaconda3/envs/ghifo_py38/lib/python3.8/site-packages/tensorflow/python/ops/script_ops.py", line 247, in __call__
    return func(device, token, args)

  File "/home/jruizmunoz/anaconda3/envs/ghifo_py38/lib/python3.8/site-packages/tensorflow/python/ops/script_ops.py", line 135, in __call__
    ret = self._func(*args)

  File "/home/jruizmunoz/anaconda3/envs/ghifo_py38/lib/python3.8/site-packages/tensorflow/python/autograph/impl/api.py", line 645, in wrapper
    return func(*args, **kwargs)

  File "/home/jruizmunoz/anaconda3/envs/ghifo_py38/lib/python3.8/site-packages/tensorflow/python/data/ops/dataset_ops.py", line 977, in generator_py_func
    raise TypeError(

TypeError: `generator` yielded an element of ((TensorSpec(shape=(40, 420), dtype=tf.float64, name=None), SparseTensorSpec(TensorShape([40, 40]), tf.float32), TensorSpec(shape=(40,), dtype=tf.int64, name=None)), TensorSpec(shape=(8, 5, 12), dtype=tf.int64, name=None)) where an element of ((TensorSpec(shape=(None, 420), dtype=tf.float64, name=None), SparseTensorSpec(TensorShape([None, None]), tf.float32), TensorSpec(shape=(None,), dtype=tf.int64, name=None)), TensorSpec(shape=(None, 12), dtype=tf.int64, name=None)) was expected.


	 [[{{node EagerPyFunc}}]]
	 [[IteratorGetNext]]
	 [[DeserializeSparse/_8]]
0 successful operations.
0 derived errors ignored. [Op:__inference_train_function_997]

Function call stack:
train_function -> train_function

2025-07-09 08:52:24.905353: W tensorflow/core/kernels/data/generator_dataset_op.cc:107] Error occurred when finalizing GeneratorDataset iterator: Failed precondition: Python interpreter state is not initialized. The process may be terminated.
	 [[{{node PyFunc}}]]
