
Currently Loaded Modules:
  1) tensorflow/2.6.0

 

2025-07-08 20:17:59.273963: W tensorflow/core/common_runtime/gpu/gpu_device.cc:1938] TensorFlow was not built with CUDA kernel binaries compatible with compute capability 10.0. CUDA kernels will be jit-compiled from PTX, which could take 30 minutes or longer.
2025-07-08 20:18:54.762872: W tensorflow/core/common_runtime/gpu/gpu_device.cc:1938] TensorFlow was not built with CUDA kernel binaries compatible with compute capability 10.0. CUDA kernels will be jit-compiled from PTX, which could take 30 minutes or longer.
2025-07-08 20:18:54.763574: I tensorflow/core/platform/cpu_feature_guard.cc:142] This TensorFlow binary is optimized with oneAPI Deep Neural Network Library (oneDNN) to use the following CPU instructions in performance-critical operations:  AVX2 AVX512F FMA
To enable them in other operations, rebuild TensorFlow with the appropriate compiler flags.
2025-07-08 20:18:54.768921: W tensorflow/core/common_runtime/gpu/gpu_device.cc:1938] TensorFlow was not built with CUDA kernel binaries compatible with compute capability 10.0. CUDA kernels will be jit-compiled from PTX, which could take 30 minutes or longer.
2025-07-08 20:19:07.951732: I tensorflow/core/common_runtime/gpu/gpu_device.cc:1510] Created device /job:localhost/replica:0/task:0/device:GPU:0 with 180450 MB memory:  -> device: 0, name: NVIDIA B200, pci bus id: 0000:9d:00.0, compute capability: 10.0
2025-07-08 20:19:10.440682: I tensorflow/compiler/mlir/mlir_graph_optimization_pass.cc:185] None of the MLIR Optimization Passes are enabled (registered 2)
<frozen importlib._bootstrap>:219: RuntimeWarning: scipy._lib.messagestream.MessageStream size changed, may indicate binary incompatibility. Expected 56 from C header, got 64 from PyObject
Traceback (most recent call last):
  File "train_gnn.py", line 283, in <module>
    main()
  File "train_gnn.py", line 275, in main
    model.fit(loader.load(), steps_per_epoch=loader.steps_per_epoch, epochs=20)
  File "/home/jruizmunoz/anaconda3/envs/ghifo_py38/lib/python3.8/site-packages/keras/engine/training.py", line 1184, in fit
    tmp_logs = self.train_function(iterator)
  File "/home/jruizmunoz/anaconda3/envs/ghifo_py38/lib/python3.8/site-packages/tensorflow/python/eager/def_function.py", line 885, in __call__
    result = self._call(*args, **kwds)
  File "/home/jruizmunoz/anaconda3/envs/ghifo_py38/lib/python3.8/site-packages/tensorflow/python/eager/def_function.py", line 933, in _call
    self._initialize(args, kwds, add_initializers_to=initializers)
  File "/home/jruizmunoz/anaconda3/envs/ghifo_py38/lib/python3.8/site-packages/tensorflow/python/eager/def_function.py", line 759, in _initialize
    self._stateful_fn._get_concrete_function_internal_garbage_collected(  # pylint: disable=protected-access
  File "/home/jruizmunoz/anaconda3/envs/ghifo_py38/lib/python3.8/site-packages/tensorflow/python/eager/function.py", line 3066, in _get_concrete_function_internal_garbage_collected
    graph_function, _ = self._maybe_define_function(args, kwargs)
  File "/home/jruizmunoz/anaconda3/envs/ghifo_py38/lib/python3.8/site-packages/tensorflow/python/eager/function.py", line 3463, in _maybe_define_function
    graph_function = self._create_graph_function(args, kwargs)
  File "/home/jruizmunoz/anaconda3/envs/ghifo_py38/lib/python3.8/site-packages/tensorflow/python/eager/function.py", line 3298, in _create_graph_function
    func_graph_module.func_graph_from_py_func(
  File "/home/jruizmunoz/anaconda3/envs/ghifo_py38/lib/python3.8/site-packages/tensorflow/python/framework/func_graph.py", line 1007, in func_graph_from_py_func
    func_outputs = python_func(*func_args, **func_kwargs)
  File "/home/jruizmunoz/anaconda3/envs/ghifo_py38/lib/python3.8/site-packages/tensorflow/python/eager/def_function.py", line 668, in wrapped_fn
    out = weak_wrapped_fn().__wrapped__(*args, **kwds)
  File "/home/jruizmunoz/anaconda3/envs/ghifo_py38/lib/python3.8/site-packages/tensorflow/python/framework/func_graph.py", line 994, in wrapper
    raise e.ag_error_metadata.to_exception(e)
ValueError: in user code:

    /home/jruizmunoz/anaconda3/envs/ghifo_py38/lib/python3.8/site-packages/keras/engine/training.py:853 train_function  *
        return step_function(self, iterator)
    /home/jruizmunoz/anaconda3/envs/ghifo_py38/lib/python3.8/site-packages/keras/engine/training.py:842 step_function  **
        outputs = model.distribute_strategy.run(run_step, args=(data,))
    /home/jruizmunoz/anaconda3/envs/ghifo_py38/lib/python3.8/site-packages/tensorflow/python/distribute/distribute_lib.py:1286 run
        return self._extended.call_for_each_replica(fn, args=args, kwargs=kwargs)
    /home/jruizmunoz/anaconda3/envs/ghifo_py38/lib/python3.8/site-packages/tensorflow/python/distribute/distribute_lib.py:2849 call_for_each_replica
        return self._call_for_each_replica(fn, args, kwargs)
    /home/jruizmunoz/anaconda3/envs/ghifo_py38/lib/python3.8/site-packages/tensorflow/python/distribute/distribute_lib.py:3632 _call_for_each_replica
        return fn(*args, **kwargs)
    /home/jruizmunoz/anaconda3/envs/ghifo_py38/lib/python3.8/site-packages/keras/engine/training.py:835 run_step  **
        outputs = model.train_step(data)
    /home/jruizmunoz/anaconda3/envs/ghifo_py38/lib/python3.8/site-packages/keras/engine/training.py:787 train_step
        y_pred = self(x, training=True)
    /home/jruizmunoz/anaconda3/envs/ghifo_py38/lib/python3.8/site-packages/keras/engine/base_layer.py:1020 __call__
        input_spec.assert_input_compatibility(self.input_spec, inputs, self.name)
    /home/jruizmunoz/anaconda3/envs/ghifo_py38/lib/python3.8/site-packages/keras/engine/input_spec.py:199 assert_input_compatibility
        raise ValueError('Layer ' + layer_name + ' expects ' +

    ValueError: Layer model expects 2 input(s), but it received 3 input tensors. Inputs received: [<tf.Tensor 'IteratorGetNext:0' shape=(None, 420) dtype=float64>, <tensorflow.python.framework.sparse_tensor.SparseTensor object at 0x155465296670>, <tf.Tensor 'ExpandDims:0' shape=(None, 1) dtype=int64>]

